2023-03-23 16:02:20,200 INFO    MainThread:6800 [wandb_setup.py:_flush():76] Configure stats pid to 6800
2023-03-23 16:02:20,201 INFO    MainThread:6800 [wandb_setup.py:_flush():76] Loading settings from C:\Users\fdani\.config\wandb\settings
2023-03-23 16:02:20,201 INFO    MainThread:6800 [wandb_setup.py:_flush():76] Loading settings from D:\fdani\Documents\ACADS\4th Year\1st Semester\EEE 196\Code\MobileNetV2_FSLModel\wandb\settings
2023-03-23 16:02:20,201 INFO    MainThread:6800 [wandb_setup.py:_flush():76] Loading settings from environment variables: {}
2023-03-23 16:02:20,202 INFO    MainThread:6800 [wandb_setup.py:_flush():76] Applying setup settings: {'_disable_service': False}
2023-03-23 16:02:20,202 INFO    MainThread:6800 [wandb_setup.py:_flush():76] Inferring run settings from compute environment: {'program_relpath': 'train.py', 'program': 'd:\\fdani\\Documents\\ACADS\\4th Year\\1st Semester\\EEE 196\\Code\\MobileNetV2_FSLModel\\train.py'}
2023-03-23 16:02:20,204 INFO    MainThread:6800 [wandb_init.py:_log_setup():506] Logging user logs to D:\fdani\Documents\ACADS\4th Year\1st Semester\EEE 196\Code\MobileNetV2_FSLModel\wandb\run-20230323_160220-ba7rkc9c\logs\debug.log
2023-03-23 16:02:20,205 INFO    MainThread:6800 [wandb_init.py:_log_setup():507] Logging internal logs to D:\fdani\Documents\ACADS\4th Year\1st Semester\EEE 196\Code\MobileNetV2_FSLModel\wandb\run-20230323_160220-ba7rkc9c\logs\debug-internal.log
2023-03-23 16:02:20,207 INFO    MainThread:6800 [wandb_init.py:init():546] calling init triggers
2023-03-23 16:02:20,207 INFO    MainThread:6800 [wandb_init.py:init():552] wandb.init called with sweep_config: {}
config: {'learning_rate': 0.001, 'architecture': 'CNN', 'dataset': 'Custom FSL Dataset', 'epochs': 20}
2023-03-23 16:02:20,209 INFO    MainThread:6800 [wandb_init.py:init():602] starting backend
2023-03-23 16:02:20,209 INFO    MainThread:6800 [wandb_init.py:init():606] setting up manager
2023-03-23 16:02:20,225 INFO    MainThread:6800 [backend.py:_multiprocessing_setup():106] multiprocessing start_methods=spawn, using: spawn
2023-03-23 16:02:20,246 INFO    MainThread:6800 [wandb_init.py:init():613] backend started and connected
2023-03-23 16:02:20,268 INFO    MainThread:6800 [wandb_init.py:init():701] updated telemetry
2023-03-23 16:02:20,385 INFO    MainThread:6800 [wandb_init.py:init():741] communicating run to backend with 60.0 second timeout
2023-03-23 16:02:34,362 INFO    Thread-7 (wrapped_target):6800 [retry.py:__call__():172] Retry attempt failed:
Traceback (most recent call last):
  File "C:\Users\fdani\anaconda3\envs\dl_course\lib\site-packages\urllib3\connection.py", line 174, in _new_conn
    conn = connection.create_connection(
  File "C:\Users\fdani\anaconda3\envs\dl_course\lib\site-packages\urllib3\util\connection.py", line 72, in create_connection
    for res in socket.getaddrinfo(host, port, family, socket.SOCK_STREAM):
  File "C:\Users\fdani\anaconda3\envs\dl_course\lib\socket.py", line 955, in getaddrinfo
    for res in _socket.getaddrinfo(host, port, family, type, proto, flags):
socket.gaierror: [Errno 11001] getaddrinfo failed

During handling of the above exception, another exception occurred:

Traceback (most recent call last):
  File "C:\Users\fdani\anaconda3\envs\dl_course\lib\site-packages\urllib3\connectionpool.py", line 703, in urlopen
    httplib_response = self._make_request(
  File "C:\Users\fdani\anaconda3\envs\dl_course\lib\site-packages\urllib3\connectionpool.py", line 386, in _make_request
    self._validate_conn(conn)
  File "C:\Users\fdani\anaconda3\envs\dl_course\lib\site-packages\urllib3\connectionpool.py", line 1042, in _validate_conn
    conn.connect()
  File "C:\Users\fdani\anaconda3\envs\dl_course\lib\site-packages\urllib3\connection.py", line 358, in connect
    self.sock = conn = self._new_conn()
  File "C:\Users\fdani\anaconda3\envs\dl_course\lib\site-packages\urllib3\connection.py", line 186, in _new_conn
    raise NewConnectionError(
urllib3.exceptions.NewConnectionError: <urllib3.connection.HTTPSConnection object at 0x000001F511578B20>: Failed to establish a new connection: [Errno 11001] getaddrinfo failed

During handling of the above exception, another exception occurred:

Traceback (most recent call last):
  File "C:\Users\fdani\anaconda3\envs\dl_course\lib\site-packages\requests\adapters.py", line 489, in send
    resp = conn.urlopen(
  File "C:\Users\fdani\anaconda3\envs\dl_course\lib\site-packages\urllib3\connectionpool.py", line 787, in urlopen
    retries = retries.increment(
  File "C:\Users\fdani\anaconda3\envs\dl_course\lib\site-packages\urllib3\util\retry.py", line 592, in increment
    raise MaxRetryError(_pool, url, error or ResponseError(cause))
urllib3.exceptions.MaxRetryError: HTTPSConnectionPool(host='api.wandb.ai', port=443): Max retries exceeded with url: /graphql (Caused by NewConnectionError('<urllib3.connection.HTTPSConnection object at 0x000001F511578B20>: Failed to establish a new connection: [Errno 11001] getaddrinfo failed'))

During handling of the above exception, another exception occurred:

Traceback (most recent call last):
  File "C:\Users\fdani\anaconda3\envs\dl_course\lib\site-packages\wandb\sdk\lib\retry.py", line 131, in __call__
    result = self._call_fn(*args, **kwargs)
  File "C:\Users\fdani\anaconda3\envs\dl_course\lib\site-packages\wandb\sdk\internal\internal_api.py", line 242, in execute
    return self.client.execute(*args, **kwargs)  # type: ignore
  File "C:\Users\fdani\anaconda3\envs\dl_course\lib\site-packages\wandb\vendor\gql-0.2.0\wandb_gql\client.py", line 52, in execute
    result = self._get_result(document, *args, **kwargs)
  File "C:\Users\fdani\anaconda3\envs\dl_course\lib\site-packages\wandb\vendor\gql-0.2.0\wandb_gql\client.py", line 60, in _get_result
    return self.transport.execute(document, *args, **kwargs)
  File "C:\Users\fdani\anaconda3\envs\dl_course\lib\site-packages\wandb\vendor\gql-0.2.0\wandb_gql\transport\requests.py", line 38, in execute
    request = requests.post(self.url, **post_args)
  File "C:\Users\fdani\anaconda3\envs\dl_course\lib\site-packages\requests\api.py", line 115, in post
    return request("post", url, data=data, json=json, **kwargs)
  File "C:\Users\fdani\anaconda3\envs\dl_course\lib\site-packages\requests\api.py", line 59, in request
    return session.request(method=method, url=url, **kwargs)
  File "C:\Users\fdani\anaconda3\envs\dl_course\lib\site-packages\requests\sessions.py", line 587, in request
    resp = self.send(prep, **send_kwargs)
  File "C:\Users\fdani\anaconda3\envs\dl_course\lib\site-packages\requests\sessions.py", line 701, in send
    r = adapter.send(request, **kwargs)
  File "C:\Users\fdani\anaconda3\envs\dl_course\lib\site-packages\requests\adapters.py", line 565, in send
    raise ConnectionError(e, request=request)
requests.exceptions.ConnectionError: HTTPSConnectionPool(host='api.wandb.ai', port=443): Max retries exceeded with url: /graphql (Caused by NewConnectionError('<urllib3.connection.HTTPSConnection object at 0x000001F511578B20>: Failed to establish a new connection: [Errno 11001] getaddrinfo failed'))
2023-03-23 16:02:50,449 INFO    MainThread:6800 [wandb_run.py:_on_init():2131] communicating current version
2023-03-23 16:02:51,385 INFO    MainThread:6800 [wandb_run.py:_on_init():2140] got version response upgrade_message: "wandb version 0.14.0 is available!  To upgrade, please run:\n $ pip install wandb --upgrade"

2023-03-23 16:02:51,385 INFO    MainThread:6800 [wandb_init.py:init():789] starting run threads in backend
2023-03-23 16:03:06,463 INFO    MainThread:6800 [wandb_run.py:_console_start():2112] atexit reg
2023-03-23 16:03:06,466 INFO    MainThread:6800 [wandb_run.py:_redirect():1967] redirect: SettingsConsole.WRAP_RAW
2023-03-23 16:03:06,466 INFO    MainThread:6800 [wandb_run.py:_redirect():2032] Wrapping output streams.
2023-03-23 16:03:06,467 INFO    MainThread:6800 [wandb_run.py:_redirect():2057] Redirects installed.
2023-03-23 16:03:06,468 INFO    MainThread:6800 [wandb_init.py:init():831] run started, returning control to user process
2023-03-23 16:50:41,130 WARNING MsgRouterThr:6800 [router.py:message_loop():77] message_loop has been closed
